Workbook

Sheet Fleet Data
A1: Vehicle ID | B1: Vehicle Type | C1: County | D1: Department | E1: Fuel Type | F1: Engine CC | G1: Year of Manufacture | H1: Odometer (km) | I1: Fuel Consumed (L) | J1: Fuel Cost (KES) | K1: Maintenance Cost (KES) | L1: Total Cost (KES) | M1: Status | N1: Utilization Rate (%) | O1: Cost per km (KES) | Q1: FLEET KPI SUMMARY
A2: VH-0001 | B2: Lorry | C2: Nairobi | D2: Maintenance | E2: Diesel | F2: 3000 | G2: 2013 | H2: 88158 | I2: 13545.2 | J2: 2438136 | K2: 86053 | L2: =J2+K2 -> 2524189 | M2: Active | N2: 49.6 | O2: =IF(H2>0,L2/H2,0) -> 28.632557 | Q2: Total Vehicles | R2: =COUNTA(A2:A201) -> 200
A3: VH-0002 | B3: Forklift | C3: Nairobi | D3: Construction | E3: Diesel | F3: 2500 | G3: 2013 | H3: 136981 | I3: 17880.9 | J3: 3218562 | K3: 17786 | L3: =J3+K3 -> 3236348 | M3: Active | N3: 79.4 | O3: =IF(H3>0,L3/H3,0) -> 23.626255 | Q3: Active Vehicles | R3: =COUNTIF(M2:M201,"Active") -> 184
A4: VH-0003 | B4: Minivan | C4: Nyeri | D4: Logistics | E4: Petrol | F4: 4000 | G4: 2019 | H4: 160852 | I4: 25888 | J4: 5048160 | K4: 15682 | L4: =J4+K4 -> 5063842 | M4: Active | N4: 82 | O4: =IF(H4>0,L4/H4,0) -> 31.481374 | Q4: Under Repair | R4: =COUNTIF(M2:M201,"Under Repair") -> 11
A5: VH-0004 | B5: Excavator | C5: Eldoret | D5: Logistics | E5: Diesel | F5: 3000 | G5: 2022 | H5: 191472 | I5: 17274.8 | J5: 3109464 | K5: 54892 | L5: =J5+K5 -> 3164356 | M5: Active | N5: 63.2 | O5: =IF(H5>0,L5/H5,0) -> 16.526469 | Q5: Inactive | R5: =COUNTIF(M2:M201,"Inactive") -> 5
A6: VH-0005 | B6: Crane | C6: Kisii | D6: Construction | E6: Diesel | F6: 5000 | G6: 2017 | H6: 80444 | I6: 14263.7 | J6: 2567466 | K6: 54746 | L6: =J6+K6 -> 2622212 | M6: Active | N6: 89 | O6: =IF(H6>0,L6/H6,0) -> 32.596738 | Q6: Total Fleet Cost (KES) | R6: =SUM(L2:L201) -> 710114919
A7: VH-0006 | B7: Tanker | C7: Lamu | D7: Maintenance | E7: Diesel | F7: 4500 | G7: 2013 | H7: 51466 | I7: 4353.1 | J7: 783558 | K7: 38929 | L7: =J7+K7 -> 822487 | M7: Active | N7: 49.2 | O7: =IF(H7>0,L7/H7,0) -> 15.981172 | Q7: Avg Utilization (%) | R7: =AVERAGE(N2:N201) -> 68.3735
A8: VH-0007 | B8: Tipper | C8: Kakamega | D8: Construction | E8: Diesel | F8: 4000 | G8: 2014 | H8: 252717 | I8: 36282.2 | J8: 6530796 | K8: 53307 | L8: =J8+K8 -> 6584103 | M8: Active | N8: 56.1 | O8: =IF(H8>0,L8/H8,0) -> 26.053265 | Q8: Avg Cost/km (KES) | R8: =AVERAGE(O2:O201) -> 24.263146
A9: VH-0008 | B9: Crane | C9: Malindi | D9: Construction | E9: Diesel | F9: 4500 | G9: 2020 | H9: 104725 | I9: 13971.8 | J9: 2514924 | K9: 40705 | L9: =J9+K9 -> 2555629 | M9: Active | N9: 59.3 | O9: =IF(H9>0,L9/H9,0) -> 24.403237 | Q9: Total Fuel Consumed (L) | R9: =SUM(I2:I201) -> 3801141.6
A10: VH-0009 | B10: Minivan | C10: Nakuru | D10: Maintenance | E10: Petrol | F10: 2500 | G10: 2013 | H10: 31829 | I10: 5108.7 | J10: 996196 | K10: 57122 | L10: =J10+K10 -> 1053318 | M10: Active | N10: 93.4 | O10: =IF(H10>0,L10/H10,0) -> 33.093028
A11: VH-0010 | B11: Tanker | C11: Lamu | D11: Maintenance | E11: Diesel | F11: 3000 | G11: 2020 | H11: 276740 | I11: 33087.9 | J11: 5955822 | K11: 111027 | L11: =J11+K11 -> 6066849 | M11: Active | N11: 59 | O11: =IF(H11>0,L11/H11,0) -> 21.922559
A12: VH-0011 | B12: Tipper | C12: Malindi | D12: Supply Chain | E12: Diesel | F12: 4500 | G12: 2014 | H12: 239622 | I12: 40683.6 | J12: 7323048 | K12: 56937 | L12: =J12+K12 -> 7379985 | M12: Active | N12: 97.9 | O12: =IF(H12>0,L12/H12,0) -> 30.798445
A13: VH-0012 | B13: Minivan | C13: Machakos | D13: Construction | E13: Petrol | F13: 2500 | G13: 2011 | H13: 95132 | I13: 13579.6 | J13: 2648022 | K13: 98168 | L13: =J13+K13 -> 2746190 | M13: Active | N13: 48.4 | O13: =IF(H13>0,L13/H13,0) -> 28.867153
A14: VH-0013 | B14: Forklift | C14: Kitale | D14: Operations | E14: Diesel | F14: 4500 | G14: 2014 | H14: 21019 | I14: 3111.4 | J14: 560052 | K14: 27028 | L14: =J14+K14 -> 587080 | M14: Active | N14: 84.8 | O14: =IF(H14>0,L14/H14,0) -> 27.93092
A15: VH-0014 | B15: Excavator | C15: Mombasa | D15: Maintenance | E15: Diesel | F15: 4000 | G15: 2012 | H15: 252881 | I15: 20312.5 | J15: 3656250 | K15: 90820 | L15: =J15+K15 -> 3747070 | M15: Active | N15: 96.5 | O15: =IF(H15>0,L15/H15,0) -> 14.817523
A16: VH-0015 | B16: Pickup | C16: Meru | D16: Construction | E16: Petrol | F16: 5000 | G16: 2014 | H16: 119286 | I16: 11366 | J16: 2216370 | K16: 95064 | L16: =J16+K16 -> 2311434 | M16: Active | N16: 86.3 | O16: =IF(H16>0,L16/H16,0) -> 19.377245
A17: VH-0016 | B17: Minivan | C17: Lamu | D17: Construction | E17: Petrol | F17: 4500 | G17: 2015 | H17: 271170 | I17: 22221.8 | J17: 4333251 | K17: 112555 | L17: =J17+K17 -> 4445806 | M17: Active | N17: 89.1 | O17: =IF(H17>0,L17/H17,0) -> 16.394904
A18: VH-0017 | B18: Crane | C18: Nakuru | D18: Construction | E18: Diesel | F18: 3000 | G18: 2019 | H18: 56291 | I18: 4985.4 | J18: 897372 | K18: 66029 | L18: =J18+K18 -> 963401 | M18: Active | N18: 85.3 | O18: =IF(H18>0,L18/H18,0) -> 17.114654
A19: VH-0018 | B19: Pickup | C19: Kisumu | D19: Operations | E19: Petrol | F19: 4500 | G19: 2012 | H19: 153966 | I19: 20441.7 | J19: 3986132 | K19: 78692 | L19: =J19+K19 -> 4064824 | M19: Under Repair | N19: 37.2 | O19: =IF(H19>0,L19/H19,0) -> 26.40079
A20: VH-0019 | B20: Tipper | C20: Malindi | D20: Maintenance | E20: Diesel | F20: 4000 | G20: 2020 | H20: 210779 | I20: 26096.5 | J20: 4697370 | K20: 69345 | L20: =J20+K20 -> 4766715 | M20: Active | N20: 56.9 | O20: =IF(H20>0,L20/H20,0) -> 22.614753
A21: VH-0020 | B21: Excavator | C21: Nairobi | D21: Supply Chain | E21: Diesel | F21: 4500 | G21: 2013 | H21: 130457 | I21: 10530.4 | J21: 1895472 | K21: 89323 | L21: =J21+K21 -> 1984795 | M21: Active | N21: 48.6 | O21: =IF(H21>0,L21/H21,0) -> 15.21417
... A201: VH-0200 | B201: Truck | C201: Mombasa | D201: Operations | E201: Diesel | F201: 4500 | G201: 2017 | H201: 141211 | I201: 14335 | J201: 2580300 | K201: 52054 | L201: =J201+K201 -> 2632354 | M201: Active | N201: 71.2 | O201: =IF(H201>0,L201/H201,0) -> 18.641281

Sheet Machinery Log
A1: Log ID | B1: Machinery Type | C1: Site Location | D1: County | E1: Operator | F1: Date | G1: Hours Operated | H1: Planned Hours | I1: Utilization (%) | J1: Fuel Used (L) | K1: Fuel Cost (KES) | L1: Breakdown Incidents | M1: Condition | N1: Downtime (hrs) | O1: Efficiency Score
A2: ML-0001 | B2: Compressor | C2: Eldoret Industrial | D2: Uasin Gishu | E2: Operator C | F2: 2025-01-24 | G2: 7.6 | H2: 12 | I2: =IF(H2>0,G2/H2*100,0) -> 63.333333 | J2: 102.6 | K2: 18468 | L2: 0 | M2: Fair | N2: 1.8 | O2: =IF(I2>0,I2*(1-N2/H2),0) -> 53.833333
A3: ML-0002 | B3: Grader | C3: Thika Road | D3: Kiambu | E3: Operator M | F3: 2024-12-09 | G3: 7.3 | H3: 10 | I3: =IF(H3>0,G3/H3*100,0) -> 73 | J3: 85.1 | K3: 15318 | L3: 0 | M3: Fair | N3: 1.2 | O3: =IF(I3>0,I3*(1-N3/H3),0) -> 64.24
A4: ML-0003 | B4: Excavator | C4: Nairobi Bypass | D4: Nairobi | E4: Operator B | F4: 2024-05-10 | G4: 8.8 | H4: 10 | I4: =IF(H4>0,G4/H4*100,0) -> 88 | J4: 116.1 | K4: 20898 | L4: 0 | M4: Fair | N4: 0.4 | O4: =IF(I4>0,I4*(1-N4/H4),0) -> 84.48
A5: ML-0004 | B5: Drilling Rig | C5: Nyeri Dam | D5: Nyeri | E5: Operator F | F5: 2025-01-24 | G5: 9.9 | H5: 12 | I5: =IF(H5>0,G5/H5*100,0) -> 82.5 | J5: 108.8 | K5: 19584 | L5: 0 | M5: Fair | N5: 1.6 | O5: =IF(I5>0,I5*(1-N5/H5),0) -> 71.5
A6: ML-0005 | B6: Drilling Rig | C6: Eldoret Industrial | D6: Uasin Gishu | E6: Operator P | F6: 2024-01-27 | G6: 6 | H6: 10 | I6: =IF(H6>0,G6/H6*100,0) -> 60 | J6: 54.6 | K6: 9828 | L6: 0 | M6: Good | N6: 2.7 | O6: =IF(I6>0,I6*(1-N6/H6),0) -> 43.8
A7: ML-0006 | B7: Excavator | C7: Kitale Grain Store | D7: Trans-Nzoia | E7: Operator P | F7: 2024-09-04 | G7: 8.6 | H7: 12 | I7: =IF(H7>0,G7/H7*100,0) -> 71.666667 | J7: 130.8 | K7: 23544 | L7: 0 | M7: Good | N7: 1.9 | O7: =IF(I7>0,I7*(1-N7/H7),0) -> 60.319444
A8: ML-0007 | B8: Drilling Rig | C8: Nakuru Ring Road | D8: Nakuru | E8: Operator E | F8: 2025-10-18 | G8: 4.2 | H8: 9 | I8: =IF(H8>0,G8/H8*100,0) -> 46.666667 | J8: 73.4 | K8: 13212 | L8: 0 | M8: Good | N8: 0.9 | O8: =IF(I8>0,I8*(1-N8/H8),0) -> 42
A9: ML-0008 | B9: Grader | C9: Nakuru Ring Road | D9: Nakuru | E9: Operator G | F9: 2025-02-12 | G9: 10.2 | H9: 12 | I9: =IF(H9>0,G9/H9*100,0) -> 85 | J9: 175.5 | K9: 31590 | L9: 0 | M9: Fair | N9: 0.2 | O9: =IF(I9>0,I9*(1-N9/H9),0) -> 83.583333
A10: ML-0009 | B10: Grader | C10: Malindi Resort | D10: Kilifi | E10: Operator G | F10: 2025-06-02 | G10: 10 | H10: 10 | I10: =IF(H10>0,G10/H10*100,0) -> 100 | J10: 127.8 | K10: 23004 | L10: 0 | M10: Under Service | N10: 1.4 | O10: =IF(I10>0,I10*(1-N10/H10),0) -> 86
A11: ML-0010 | B11: Compressor | C11: Nyeri Dam | D11: Nyeri | E11: Operator R | F11: 2024-12-09 | G11: 7.7 | H11: 10 | I11: =IF(H11>0,G11/H11*100,0) -> 77 | J11: 76.4 | K11: 13752 | L11: 0 | M11: Good | N11: 0.7 | O11: =IF(I11>0,I11*(1-N11/H11),0) -> 71.61
A12: ML-0011 | B12: Crane | C12: Eldoret Industrial | D12: Uasin Gishu | E12: Operator G | F12: 2025-11-07 | G12: 6.2 | H12: 11 | I12: =IF(H12>0,G12/H12*100,0) -> 56.363636 | J12: 71.2 | K12: 12816 | L12: 1 | M12: Fair | N12: 2.4 | O12: =IF(I12>0,I12*(1-N12/H12),0) -> 44.066116
A13: ML-0012 | B13: Bulldozer | C13: Kitale Grain Store | D13: Trans-Nzoia | E13: Operator R | F13: 2025-01-24 | G13: 9.7 | H13: 11 | I13: =IF(H13>0,G13/H13*100,0) -> 88.181818 | J13: 170.2 | K13: 30636 | L13: 0 | M13: Good | N13: 0.9 | O13: =IF(I13>0,I13*(1-N13/H13),0) -> 80.966942
... A301: ML-0300 | B301: Crane | C301: Thika Road | D301: Kiambu | E301: Operator N | F301: 2025-09-19 | G301: 6.6 | H301: 9 | I301: =IF(H301>0,G301/H301*100,0) -> 73.333333 | J301: 105.6 | K301: 19008 | L301: 0 | M301: Fair | N301: 0.8 | O301: =IF(I301>0,I301*(1-N301/H301),0) -> 66.814815

Sheet Purchase Orders
A1: PO Number | B1: Supplier | C1: Supplier County | D1: Category | E1: Order Date | F1: Expected Delivery | G1: Actual Delivery | H1: Lead Time (Days) | I1: Delay (Days) | J1: Quantity | K1: Unit Price (KES) | L1: Total Value (KES) | M1: Status | N1: Payment Terms | O1: On-Time?
A2: PO-00001 | B2: Highland Machinery | C2: Eldoret | D2: Safety Gear | E2: 2025-08-13 | F2: 2025-09-02 | H2: 20 | I2: 0 | J2: 56 | K2: 48781 | L2: =J2*K2 -> 2731736 | M2: In Transit | N2: Advance | O2: N/A
A3: PO-00002 | B3: Savanna Auto Parts | C3: Mombasa | D3: Tyres & Batteries | E3: 2025-03-02 | F3: 2025-04-16 | H3: 45 | I3: 12 | J3: 219 | K3: 51947 | L3: =J3*K3 -> 11376393 | M3: Delayed | N3: COD | O3: N/A
A4: PO-00003 | B4: Kilimanjaro Logistics | C4: Arusha | D4: Office Supplies | E4: 2025-05-24 | F4: 2025-06-08 | H4: 15 | I4: 0 | J4: 255 | K4: 44415 | L4: =J4*K4 -> 11325825 | M4: In Transit | N4: 60 Days Net | O4: N/A
A5: PO-00004 | B5: Coastal Spares Ltd | C5: Mombasa | D5: Heavy Equipment | E5: 2024-11-21 | F5: 2024-12-12 | H5: 21 | I5: 0 | J5: 100 | K5: 634 | L5: =J5*K5 -> 63400 | M5: In Transit | N5: 30 Days Net | O5: N/A
A6: PO-00005 | B6: Coastal Spares Ltd | C6: Mombasa | D6: Fuel & Lubricants | E6: 2024-04-18 | F6: 2024-05-08 | H6: 20 | I6: 0 | J6: 213 | K6: 35486 | L6: =J6*K6 -> 7558518 | M6: In Transit | N6: COD | O6: N/A
A7: PO-00006 | B7: Dawa Industrial | C7: Kisumu | D7: Safety Gear | E7: 2025-12-24 | F7: 2025-12-31 | H7: 7 | I7: 0 | J7: 354 | K7: 24297 | L7: =J7*K7 -> 8601138 | M7: In Transit | N7: 30 Days Net | O7: N/A
A8: PO-00007 | B8: Kilimanjaro Logistics | C8: Arusha | D8: IT & Electronics | E8: 2024-07-25 | F8: 2024-09-02 | G8: 2024-09-02 | H8: 39 | I8: 0 | J8: 352 | K8: 28662 | L8: =J8*K8 -> 10089024 | M8: Delivered | N8: 60 Days Net | O8: YES
A9: PO-00008 | B9: Boma Parts & Tools | C9: Thika | D9: Spare Parts | E9: 2025-06-04 | F9: 2025-06-22 | G9: 2025-06-22 | H9: 18 | I9: 0 | J9: 345 | K9: 40985 | L9: =J9*K9 -> 14139825 | M9: Delivered | N9: 60 Days Net | O9: YES
A10: PO-00009 | B10: Twiga Supplies Ltd | C10: Nairobi | D10: Heavy Equipment | E10: 2024-02-05 | F10: 2024-03-13 | G10: 2024-03-13 | H10: 37 | I10: 0 | J10: 275 | K10: 76206 | L10: =J10*K10 -> 20956650 | M10: Delivered | N10: 60 Days Net | O10: YES
A11: PO-00010 | B11: Pan Africa Fuels | C11: Nairobi | D11: Spare Parts | E11: 2025-11-19 | F11: 2025-12-29 | G11: 2025-12-29 | H11: 40 | I11: 0 | J11: 285 | K11: 45782 | L11: =J11*K11 -> 13047870 | M11: Delivered | N11: 14 Days Net | O11: YES
A12: PO-00011 | B12: Boma Parts & Tools | C12: Thika | D12: Office Supplies | E12: 2025-09-05 | F12: 2025-10-04 | G12: 2025-10-04 | H12: 29 | I12: 0 | J12: 16 | K12: 29158 | L12: =J12*K12 -> 466528 | M12: Delivered | N12: 60 Days Net | O12: YES
A13: PO-00012 | B13: Highland Machinery | C13: Eldoret | D13: Heavy Equipment | E13: 2024-08-02 | F13: 2024-09-14 | H13: 43 | I13: 0 | J13: 96 | K13: 50794 | L13: =J13*K13 -> 4876224 | M13: In Transit | N13: COD | O13: N/A
A14: PO-00013 | B14: Dawa Industrial | C14: Kisumu | D14: Spare Parts | E14: 2025-10-13 | F14: 2025-11-06 | G14: 2025-11-06 | H14: 24 | I14: 0 | J14: 191 | K14: 38686 | L14: =J14*K14 -> 7389026 | M14: Delivered | N14: COD | O14: YES
A15: PO-00014 | B15: East Africa Equipment | C15: Nairobi | D15: IT & Electronics | E15: 2024-06-16 | F15: 2024-07-04 | G15: 2024-07-04 | H15: 18 | I15: 0 | J15: 104 | K15: 77678 | L15: =J15*K15 -> 8078512 | M15: Delivered | N15: 60 Days Net | O15: YES
A16: PO-00015 | B16: Highland Machinery | C16: Eldoret | D16: Spare Parts | E16: 2025-11-21 | F16: 2025-12-28 | H16: 37 | I16: 0 | J16: 79 | K16: 16573 | L16: =J16*K16 -> 1309267 | M16: Pending | N16: 60 Days Net | O16: N/A
A17: PO-00016 | B17: Highland Machinery | C17: Eldoret | D17: IT & Electronics | E17: 2024-02-04 | F17: 2024-03-02 | G17: 2024-03-02 | H17: 27 | I17: 0 | J17: 481 | K17: 44114 | L17: =J17*K17 -> 21218834 | M17: Delivered | N17: 14 Days Net | O17: YES
A18: PO-00017 | B18: East Africa Equipment | C18: Nairobi | D18: Spare Parts | E18: 2025-06-18 | F18: 2025-07-24 | G18: 2025-07-24 | H18: 36 | I18: 0 | J18: 3 | K18: 26778 | L18: =J18*K18 -> 80334 | M18: Delivered | N18: 30 Days Net | O18: YES
A19: PO-00018 | B19: Boma Parts & Tools | C19: Thika | D19: Fuel & Lubricants | E19: 2024-11-13 | F19: 2024-12-11 | G19: 2024-12-11 | H19: 28 | I19: 0 | J19: 393 | K19: 56184 | L19: =J19*K19 -> 22080312 | M19: Delivered | N19: COD | O19: YES
A20: PO-00019 | B20: Twiga Supplies Ltd | C20: Nairobi | D20: IT & Electronics | E20: 2024-12-11 | F20: 2024-12-31 | G20: 2024-12-31 | H20: 20 | I20: 0 | J20: 273 | K20: 27468 | L20: =J20*K20 -> 7498764 | M20: Delivered | N20: 60 Days Net | O20: YES
A21: PO-00020 | B21: Savanna Auto Parts | C21: Mombasa | D21: IT & Electronics | E21: 2024-06-12 | F21: 2024-06-28 | G21: 2024-06-28 | H21: 16 | I21: 0 | J21: 319 | K21: 47788 | L21: =J21*K21 -> 15244372 | M21: Delivered | N21: 30 Days Net | O21: YES
A22: PO-00021 | B22: East Africa Equipment | C22: Nairobi | D22: Office Supplies | E22: 2025-01-05 | F22: 2025-02-16 | G22: 2025-02-19 | H22: 42 | I22: 3 | J22: 412 | K22: 24436 | L22: =J22*K22 -> 10067632 | M22: Delivered | N22: 14 Days Net | O22: NO
A23: PO-00022 | B23: Rift Valley Traders | C23: Nakuru | D23: Fuel & Lubricants | E23: 2024-12-17 | F23: 2025-01-12 | H23: 26 | I23: 0 | J23: 174 | K23: 46179 | L23: =J23*K23 -> 8035146 | M23: In Transit | N23: 30 Days Net | O23: N/A
A24: PO-00023 | B24: Rift Valley Traders | C24: Nakuru | D24: Spare Parts | E24: 2024-03-11 | F24: 2024-04-17 | H24: 37 | I24: 0 | J24: 26 | K24: 9451 | L24: =J24*K24 -> 245726 | M24: Pending | N24: 30 Days Net | O24: N/A
A25: PO-00024 | B25: Savanna Auto Parts | C25: Mombasa | D25: Construction Materials | E25: 2024-05-17 | F25: 2024-06-18 | G25: 2024-06-18 | H25: 32 | I25: 0 | J25: 323 | K25: 71157 | L25: =J25*K25 -> 22983711 | M25: Delivered | N25: 60 Days Net | O25: YES
A26: PO-00025 | B26: Boma Parts & Tools | C26: Thika | D26: Office Supplies | E26: 2024-10-09 | F26: 2024-11-04 | G26: 2024-11-04 | H26: 26 | I26: 0 | J26: 344 | K26: 68886 | L26: =J26*K26 -> 23696784 | M26: Delivered | N26: 30 Days Net | O26: YES
A27: PO-00026 | B27: Coastal Spares Ltd | C27: Mombasa | D27: Heavy Equipment | E27: 2025-12-02 | F27: 2025-12-14 | H27: 12 | I27: 0 | J27: 471 | K27: 59532 | L27: =J27*K27 -> 28039572 | M27: In Transit | N27: 30 Days Net | O27: N/A
A28: PO-00027 | B28: Coastal Spares Ltd | C28: Mombasa | D28: IT & Electronics | E28: 2025-03-26 | F28: 2025-05-01 | G28: 2025-05-01 | H28: 36 | I28: 0 | J28: 459 | K28: 52632 | L28: =J28*K28 -> 24158088 | M28: Delivered | N28: COD | O28: YES
A29: PO-00028 | B29: Pan Africa Fuels | C29: Nairobi | D29: Heavy Equipment | E29: 2025-07-07 | F29: 2025-08-04 | H29: 28 | I29: 0 | J29: 452 | K29: 27942 | L29: =J29*K29 -> 12629784 | M29: In Transit | N29: 60 Days Net | O29: N/A
A30: PO-00029 | B30: Twiga Supplies Ltd | C30: Nairobi | D30: Fuel & Lubricants | E30: 2025-09-17 | F30: 2025-10-24 | G30: 2025-10-24 | H30: 37 | I30: 0 | J30: 88 | K30: 24351 | L30: =J30*K30 -> 2142888 | M30: Delivered | N30: COD | O30: YES
A31: PO-00030 | B31: Boma Parts & Tools | C31: Thika | D31: Heavy Equipment | E31: 2025-02-04 | F31: 2025-03-15 | G31: 2025-03-15 | H31: 39 | I31: 0 | J31: 55 | K31: 28036 | L31: =J31*K31 -> 1541980 | M31: Delivered | N31: 30 Days Net | O31: YES
A32: PO-00031 | B32: Kilimanjaro Logistics | C32: Arusha | D32: Tyres & Batteries | E32: 2024-02-08 | F32: 2024-03-11 | G32: 2024-03-11 | H32: 32 | I32: 0 | J32: 281 | K32: 13937 | L32: =J32*K32 -> 3916297 | M32: Delivered | N32: 60 Days Net | O32: YES
A33: PO-00032 | B33: Pan Africa Fuels | C33: Nairobi | D33: Fuel & Lubricants | E33: 2025-11-11 | F33: 2025-12-09 | G33: 2025-12-09 | H33: 28 | I33: 0 | J33: 402 | K33: 83327 | L33: =J33*K33 -> 33497454 | M33: Delivered | N33: Advance | O33: YES
A34: PO-00033 | B34: Dawa Industrial | C34: Kisumu | D34: Safety Gear | E34: 2025-12-25 | F34: 2026-01-12 | H34: 18 | I34: 0 | J34: 40 | K34: 62977 | L34: =J34*K34 -> 2519080 | M34: In Transit | N34: Advance | O34: N/A
A35: PO-00034 | B35: Coastal Spares Ltd | C35: Mombasa | D35: Fuel & Lubricants | E35: 2024-02-18 | F35: 2024-04-02 | G35: 2024-04-02 | H35: 44 | I35: 0 | J35: 421 | K35: 38121 | L35: =J35*K35 -> 16048941 | M35: Delivered | N35: COD | O35: YES
A36: PO-00035 | B36: Pan Africa Fuels | C36: Nairobi | D36: Fuel & Lubricants | E36: 2025-08-07 | F36: 2025-09-21 | G36: 2025-09-21 | H36: 45 | I36: 0 | J36: 420 | K36: 32518 | L36: =J36*K36 -> 13657560 | M36: Delivered | N36: 60 Days Net | O36: YES
A37: PO-00036 | B37: Twiga Supplies Ltd | C37: Nairobi | D37: Fuel & Lubricants | E37: 2024-10-18 | F37: 2024-11-07 | H37: 20 | I37: 0 | J37: 455 | K37: 49575 | L37: =J37*K37 -> 22556625 | M37: In Transit | N37: 30 Days Net | O37: N/A
A38: PO-00037 | B38: Rift Valley Traders | C38: Nakuru | D38: Heavy Equipment | E38: 2024-04-25 | F38: 2024-05-30 | G38: 2024-05-30 | H38: 35 | I38: 0 | J38: 229 | K38: 17034 | L38: =J38*K38 -> 3900786 | M38: Delivered | N38: COD | O38: YES
A39: PO-00038 | B39: Kilimanjaro Logistics | C39: Arusha | D39: IT & Electronics | E39: 2025-03-27 | F39: 2025-04-30 | H39: 34 | I39: 0 | J39: 469 | K39: 29590 | L39: =J39*K39 -> 13877710 | M39: In Transit | N39: 30 Days Net | O39: N/A
A40: PO-00039 | B40: Boma Parts & Tools | C40: Thika | D40: Spare Parts | E40: 2024-10-18 | F40: 2024-11-26 | G40: 2024-11-26 | H40: 39 | I40: 0 | J40: 32 | K40: 31699 | L40: =J40*K40 -> 1014368 | M40: Delivered | N40: Advance | O40: YES
...

Sheet Delivery Tracker
A1: Delivery ID | B1: Route | C1: Origin | D1: Destination | E1: Distance (km) | F1: Scheduled Date | G1: Actual Date | H1: Scheduled Hours | I1: Actual Hours | J1: Delay (hrs) | K1: Driver | L1: Vehicle ID | M1: Load Type | N1: Load Weight (T) | O1: Delivery Status | P1: Delay Reason | Q1: Cost (KES)
A2: DL-0001 | B2: Mombasa→Nairobi | C2: Mombasa | D2: Nairobi | E2: 486 | F2: 2024-12-12 | H2: 7.3 | J2: 0 | K2: Driver K | L2: VH-0131 | M2: Food Supplies | N2: 5.3 | O2: In Progress | Q2: 78308
A3: DL-0002 | B3: Nakuru→Nairobi | C3: Nakuru | D3: Nairobi | E3: 165 | F3: 2025-07-01 | G3: 2025-07-01 | H3: 2.1 | I3: 2.6 | J3: 0.5 | K3: Driver D | L3: VH-0020 | M3: Machinery | N3: 4.2 | O3: Completed | P3: Weather | Q3: 33532
A4: DL-0003 | B4: Nairobi→Nyeri | C4: Nairobi | D4: Nyeri | E4: 160 | F4: 2025-05-05 | H4: 2.1 | J4: 0 | K4: Driver D | L4: VH-0071 | M4: Fuel | N4: 3.4 | O4: Cancelled | Q4: 23822
A5: DL-0004 | B5: Nairobi→Kisumu | C5: Nairobi | D5: Kisumu | E5: 350 | F5: 2024-03-17 | G5: 2024-03-19 | H5: 4.9 | I5: 5.4 | J5: 0.5 | K5: Driver E | L5: VH-0151 | M5: Electronics | N5: 24.3 | O5: Completed | P5: Weather | Q5: 67095
A6: DL-0005 | B6: Nairobi→Machakos | C6: Nairobi | D6: Machakos | E6: 64 | F6: 2024-01-06 | G6: 2024-01-08 | H6: 1.1 | I6: 1.6 | J6: 0.5 | K6: Driver M | L6: VH-0100 | M6: Spare Parts | N6: 10.7 | O6: Completed | P6: Load Issue | Q6: 12627
A7: DL-0006 | B7: Eldoret→Nakuru | C7: Eldoret | D7: Nakuru | E7: 135 | F7: 2025-08-19 | G7: 2025-08-21 | H7: 2.5 | I7: 2.5 | J7: 0 | K7: Driver A | L7: VH-0176 | M7: Food Supplies | N7: 21.5 | O7: Completed | P7: No Delay | Q7: 29107
A8: DL-0007 | B8: Nairobi→Mombasa | C8: Nairobi | D8: Mombasa | E8: 486 | F8: 2025-12-25 | G8: 2025-12-26 | H8: 8.5 | I8: 9.5 | J8: 1 | K8: Driver J | L8: VH-0108 | M8: Building Materials | N8: 14 | O8: Completed | P8: Load Issue | Q8: 76441
A9: DL-0008 | B9: Thika→Garissa | C9: Thika | D9: Garissa | E9: 360 | F9: 2024-05-21 | G9: 2024-05-23 | H9: 4.8 | I9: 4.5 | J9: 0 | K9: Driver E | L9: VH-0105 | M9: Electronics | N9: 9.7 | O9: Completed | P9: No Delay | Q9: 54434
A10: DL-0009 | B10: Nairobi→Kisumu | C10: Nairobi | D10: Kisumu | E10: 350 | F10: 2024-10-02 | G10: 2024-10-04 | H10: 6.7 | I10: 9.8 | J10: 3.1 | K10: Driver E | L10: VH-0142 | M10: Aggregates | N10: 24.3 | O10: Completed | P10: Load Issue | Q10: 84426
A11: DL-0010 | B11: Nairobi→Nakuru | C11: Nairobi | D11: Nakuru | E11: 165 | F11: 2025-08-17 | G11: 2025-08-19 | H11: 2.3 | I11: 2.3 | J11: 0 | K11: Driver K | L11: VH-0137 | M11: Building Materials | N11: 4.2 | O11: Completed | P11: No Delay | Q11: 19956
A12: DL-0011 | B12: Thika→Garissa | C12: Thika | D12: Garissa | E12: 360 | F12: 2025-04-24 | G12: 2025-04-26 | H12: 5.2 | I12: 7.7 | J12: 2.5 | K12: Driver O | L12: VH-0136 | M12: Building Materials | N12: 18.5 | O12: Completed | P12: Load Issue | Q12: 85498
A13: DL-0012 | B13: Nairobi→Nakuru | C13: Nairobi | D13: Nakuru | E13: 165 | F13: 2024-06-27 | G13: 2024-06-28 | H13: 3.1 | I13: 4.6 | J13: 1.5 | K13: Driver F | L13: VH-0014 | M13: Aggregates | N13: 15.1 | O13: Completed | P13: Breakdown | Q13: 37641
A14: DL-0013 | B14: Eldoret→Nakuru | C14: Eldoret | D14: Nakuru | E14: 135 | F14: 2024-05-10 | G14: 2024-05-11 | H14: 2.1 | I14: 2.2 | J14: 0.1 | K14: Driver E | L14: VH-0055 | M14: Fuel | N14: 22.3 | O14: Completed | P14: Load Issue | Q14: 30692
A15: DL-0014 | B15: Nairobi→Mombasa | C15: Nairobi | D15: Mombasa | E15: 486 | F15: 2025-10-28 | G15: 2025-10-29 | H15: 7.5 | I15: 7.2 | J15: 0 | K15: Driver F | L15: VH-0002 | M15: Food Supplies | N15: 14.1 | O15: Completed | P15: No Delay | Q15: 114563
A16: DL-0015 | B16: Nairobi→Nakuru | C16: Nairobi | D16: Nakuru | E16: 165 | F16: 2025-06-01 | H16: 3.1 | J16: 0 | K16: Driver H | L16: VH-0051 | M16: Fuel | N16: 16.1 | O16: Delayed | Q16: 28610
A17: DL-0016 | B17: Nairobi→Thika | C17: Nairobi | D17: Thika | E17: 44 | F17: 2025-01-05 | G17: 2025-01-05 | H17: 0.6 | I17: 0.7 | J17: 0.1 | K17: Driver E | L17: VH-0058 | M17: Aggregates | N17: 12.2 | O17: Completed | P17: Load Issue | Q17: 9922
A18: DL-0017 | B18: Nairobi→Kisumu | C18: Nairobi | D18: Kisumu | E18: 350 | F18: 2025-11-27 | G18: 2025-11-27 | H18: 5.5 | I18: 7.8 | J18: 2.3 | K18: Driver C | L18: VH-0091 | M18: Building Materials | N18: 13.3 | O18: Completed | P18: Traffic | Q18: 50625
A19: DL-0018 | B19: Nairobi→Mombasa | C19: Nairobi | D19: Mombasa | E19: 486 | F19: 2024-07-14 | H19: 6.7 | J19: 0 | K19: Driver O | L19: VH-0009 | M19: Spare Parts | N19: 20.2 | O19: Delayed | Q19: 118954
A20: DL-0019 | B20: Nakuru→Eldoret | C20: Nakuru | D20: Eldoret | E20: 135 | F20: 2024-07-16 | H20: 2 | J20: 0 | K20: Driver M | L20: VH-0175 | M20: Building Materials | N20: 4.3 | O20: In Progress | Q20: 29895
A21: DL-0020 | B21: Thika→Garissa | C21: Thika | D21: Garissa | E21: 360 | F21: 2025-03-04 | G21: 2025-03-04 | H21: 4.6 | I21: 6.3 | J21: 1.7 | K21: Driver M | L21: VH-0006 | M21: Spare Parts | N21: 5.1 | O21: Completed | P21: Traffic | Q21: 74945
A22: DL-0021 | B22: Nairobi→Nyeri | C22: Nairobi | D22: Nyeri | E22: 160 | F22: 2025-10-24 | H22: 3.2 | J22: 0 | K22: Driver H | L22: VH-0075 | M22: Machinery | N22: 14.8 | O22: In Progress | Q22: 24353
A23: DL-0022 | B23: Nairobi→Nakuru | C23: Nairobi | D23: Nakuru | E23: 165 | F23: 2024-04-09 | H23: 2.3 | J23: 0 | K23: Driver N | L23: VH-0068 | M23: Building Materials | N23: 7.8 | O23: In Progress | Q23: 24056
A24: DL-0023 | B24: Kisumu→Nairobi | C24: Kisumu | D24: Nairobi | E24: 350 | F24: 2024-12-24 | G24: 2024-12-24 | H24: 5.4 | I24: 5.6 | J24: 0.2 | K24: Driver C | L24: VH-0049 | M24: Electronics | N24: 17.9 | O24: Completed | P24: Route Closure | Q24: 43746
A25: DL-0024 | B25: Mombasa→Malindi | C25: Mombasa | D25: Malindi | E25: 120 | F25: 2024-07-01 | G25: 2024-07-01 | H25: 1.8 | I25: 2.3 | J25: 0.5 | K25: Driver B | L25: VH-0014 | M25: Aggregates | N25: 12.5 | O25: Completed | P25: Breakdown | Q25: 19644
A26: DL-0025 | B26: Kisumu→Kisii | C26: Kisumu | D26: Kisii | E26: 64 | F26: 2024-09-14 | H26: 0.9 | J26: 0 | K26: Driver E | L26: VH-0029 | M26: Machinery | N26: 11.2 | O26: Delayed | Q26: 13600
A27: DL-0026 | B27: Mombasa→Malindi | C27: Mombasa | D27: Malindi | E27: 120 | F27: 2025-01-06 | G27: 2025-01-08 | H27: 2.3 | I27: 2.5 | J27: 0.2 | K27: Driver A | L27: VH-0170 | M27: Building Materials | N27: 10 | O27: Completed | P27: Traffic | Q27: 21122
A28: DL-0027 | B28: Nakuru→Eldoret | C28: Nakuru | D28: Eldoret | E28: 135 | F28: 2025-06-11 | H28: 2.3 | J28: 0 | K28: Driver B | L28: VH-0172 | M28: Fuel | N28: 20.6 | O28: In Progress | Q28: 18487
A29: DL-0028 | B29: Nairobi→Nyeri | C29: Nairobi | D29: Nyeri | E29: 160 | F29: 2025-12-25 | G29: 2025-12-25 | H29: 2.4 | I29: 2.7 | J29: 0.3 | K29: Driver J | L29: VH-0096 | M29: Spare Parts | N29: 19.7 | O29: Completed | P29: Breakdown | Q29: 32295
A30: DL-0029 | B30: Nairobi→Machakos | C30: Nairobi | D30: Machakos | E30: 64 | F30: 2024-01-19 | G30: 2024-01-19 | H30: 0.8 | I30: 1.2 | J30: 0.4 | K30: Driver O | L30: VH-0168 | M30: Electronics | N30: 6.1 | O30: Completed | P30: Load Issue | Q30: 12830
A31: DL-0030 | B31: Nakuru→Eldoret | C31: Nakuru | D31: Eldoret | E31: 135 | F31: 2025-04-18 | G31: 2025-04-20 | H31: 1.9 | I31: 2.7 | J31: 0.8 | K31: Driver A | L31: VH-0033 | M31: Spare Parts | N31: 12.8 | O31: Completed | P31: Weather | Q31: 31906
A32: DL-0031 | B32: Kisumu→Kisii | C32: Kisumu | D32: Kisii | E32: 64 | F32: 2024-07-03 | G32: 2024-07-03 | H32: 1 | I32: 1.3 | J32: 0.3 | K32: Driver I | L32: VH-0129 | M32: Electronics | N32: 1.1 | O32: Completed | P32: Weather | Q32: 8058
A33: DL-0032 | B33: Nairobi→Machakos | C33: Nairobi | D33: Machakos | E33: 64 | F33: 2024-12-07 | G33: 2024-12-08 | H33: 0.9 | I33: 0.9 | J33: 0 | K33: Driver G | L33: VH-0127 | M33: Building Materials | N33: 16.2 | O33: Completed | P33: No Delay | Q33: 13926
A34: DL-0033 | B34: Thika→Garissa | C34: Thika | D34: Garissa | E34: 360 | F34: 2025-07-20 | G34: 2025-07-22 | H34: 6.2 | I34: 5.6 | J34: 0 | K34: Driver C | L34: VH-0001 | M34: Spare Parts | N34: 17.4 | O34: Completed | P34: No Delay | Q34: 64515
A35: DL-0034 | B35: Kisumu→Nairobi | C35: Kisumu | D35: Nairobi | E35: 350 | F35: 2025-05-28 | G35: 2025-05-29 | H35: 6.2 | I35: 7.6 | J35: 1.4 | K35: Driver L | L35: VH-0069 | M35: Food Supplies | N35: 4 | O35: Completed | P35: Traffic | Q35: 71102
A36: DL-0035 | B36: Nairobi→Thika | C36: Nairobi | D36: Thika | E36: 44 | F36: 2025-03-09 | G36: 2025-03-11 | H36: 0.6 | I36: 0.6 | J36: 0 | K36: Driver A | L36: VH-0165 | M36: Spare Parts | N36: 29.7 | O36: Completed | P36: No Delay | Q36: 7267
A37: DL-0036 | B37: Nairobi→Machakos | C37: Nairobi | D37: Machakos | E37: 64 | F37: 2025-06-03 | G37: 2025-06-04 | H37: 0.8 | I37: 1 | J37: 0.2 | K37: Driver O | L37: VH-0141 | M37: Machinery | N37: 21.8 | O37: Completed | P37: Traffic | Q37: 12888
A38: DL-0037 | B38: Nairobi→Mombasa | C38: Nairobi | D38: Mombasa | E38: 486 | F38: 2025-04-24 | H38: 6.2 | J38: 0 | K38: Driver C | L38: VH-0066 | M38: Fuel | N38: 16.4 | O38: Cancelled | Q38: 107486
A39: DL-0038 | B39: Nakuru→Nairobi | C39: Nakuru | D39: Nairobi | E39: 165 | F39: 2024-12-24 | G39: 2024-12-25 | H39: 2.3 | I39: 2.4 | J39: 0.1 | K39: Driver K | L39: VH-0066 | M39: Electronics | N39: 19 | O39: Completed | P39: Breakdown | Q39: 26755
A40: DL-0039 | B40: Mombasa→Malindi | C40: Mombasa | D40: Malindi | E40: 120 | F40: 2025-03-15 | G40: 2025-03-16 | H40: 2.1 | I40: 2.5 | J40: 0.4 | K40: Driver L | L40: VH-0112 | M40: Machinery | N40: 4.9 | O40: Completed | P40: Breakdown | Q40: 27123
...

Sheet Charts & Visuals
B1: KENYA FLEET & LOGISTICS — INTERACTIVE CHARTS DASHBOARD
B2: Visual analysis of fleet costs, machinery utilization, PO trends & delivery performance across Kenya
O4: Fleet by Vehicle Type
O5: Vehicle Type | P5: Count
O6: Truck | P6: =COUNTIF('Fleet Data'!B2:B201,O6) -> 10
O7: Lorry | P7: =COUNTIF('Fleet Data'!B2:B201,O7) -> 24
O8: Pickup | P8: =COUNTIF('Fleet Data'!B2:B201,O8) -> 16
O9: Tipper | P9: =COUNTIF('Fleet Data'!B2:B201,O9) -> 17
O10: Crane | P10: =COUNTIF('Fleet Data'!B2:B201,O10) -> 16
O11: Excavator | P11: =COUNTIF('Fleet Data'!B2:B201,O11) -> 27
O12: Forklift | P12: =COUNTIF('Fleet Data'!B2:B201,O12) -> 19
O13: Bus | P13: =COUNTIF('Fleet Data'!B2:B201,O13) -> 30
O14: Minivan | P14: =COUNTIF('Fleet Data'!B2:B201,O14) -> 28
O15: Tanker | P15: =COUNTIF('Fleet Data'!B2:B201,O15) -> 13
O17: Monthly PO Value Trend (2024–2025)
O18: Month | P18: PO Value (KES) | Q18: PO Count
O19: 2024-01 | P19: =SUMPRODUCT((LEFT('Purchase Orders'!E2:E481,7)=O19)*'Purchase Orders'!L2:L481) -> 268638671 | Q19: =SUMPRODUCT((LEFT('Purchase Orders'!E2:E481,7)=O19)*1) -> 20
O20: 2024-02 | P20: =SUMPRODUCT((LEFT('Purchase Orders'!E2:E481,7)=O20)*'Purchase Orders'!L2:L481) -> 252602088 | Q20: =SUMPRODUCT((LEFT('Purchase Orders'!E2:E481,7)=O20)*1) -> 20
O21: 2024-03 | P21: =SUMPRODUCT((LEFT('Purchase Orders'!E2:E481,7)=O21)*'Purchase Orders'!L2:L481) -> 134747796 | Q21: =SUMPRODUCT((LEFT('Purchase Orders'!E2:E481,7)=O21)*1) -> 20
O22: 2024-04 | P22: =SUMPRODUCT((LEFT('Purchase Orders'!E2:E481,7)=O22)*'Purchase Orders'!L2:L481) -> 187054766 | Q22: =SUMPRODUCT((LEFT('Purchase Orders'!E2:E481,7)=O22)*1) -> 20
O23: 2024-05 | P23: =SUMPRODUCT((LEFT('Purchase Orders'!E2:E481,7)=O23)*'Purchase Orders'!L2:L481) -> 196642539 | Q23: =SUMPRODUCT((LEFT('Purchase Orders'!E2:E481,7)=O23)*1) -> 20
O24: 2024-06 | P24: =SUMPRODUCT((LEFT('Purchase Orders'!E2:E481,7)=O24)*'Purchase Orders'!L2:L481) -> 191826213 | Q24: =SUMPRODUCT((LEFT('Purchase Orders'!E2:E481,7)=O24)*1) -> 20
O25: 2024-07 | P25: =SUMPRODUCT((LEFT('Purchase Orders'!E2:E481,7)=O25)*'Purchase Orders'!L2:L481) -> 228271780 | Q25: =SUMPRODUCT((LEFT('Purchase Orders'!E2:E481,7)=O25)*1) -> 20
O26: 2024-08 | P26: =SUMPRODUCT((LEFT('Purchase Orders'!E2:E481,7)=O26)*'Purchase Orders'!L2:L481) -> 206865938 | Q26: =SUMPRODUCT((LEFT('Purchase Orders'!E2:E481,7)=O26)*1) -> 20
O27: 2024-09 | P27: =SUMPRODUCT((LEFT('Purchase Orders'!E2:E481,7)=O27)*'Purchase Orders'!L2:L481) -> 151419298 | Q27: =SUMPRODUCT((LEFT('Purchase Orders'!E2:E481,7)=O27)*1) -> 20
O28: 2024-10 | P28: =SUMPRODUCT((LEFT('Purchase Orders'!E2:E481,7)=O28)*'Purchase Orders'!L2:L481) -> 228562895 | Q28: =SUMPRODUCT((LEFT('Purchase Orders'!E2:E481,7)=O28)*1) -> 20
O29: 2024-11 | P29: =SUMPRODUCT((LEFT('Purchase Orders'!E2:E481,7)=O29)*'Purchase Orders'!L2:L481) -> 201899051 | Q29: =SUMPRODUCT((LEFT('Purchase Orders'!E2:E481,7)=O29)*1) -> 20
O30: 2024-12 | P30: =SUMPRODUCT((LEFT('Purchase Orders'!E2:E481,7)=O30)*'Purchase Orders'!L2:L481) -> 188510811 | Q30: =SUMPRODUCT((LEFT('Purchase Orders'!E2:E481,7)=O30)*1) -> 20
O31: 2025-01 | P31: =SUMPRODUCT((LEFT('Purchase Orders'!E2:E481,7)=O31)*'Purchase Orders'!L2:L481) -> 216376764 | Q31: =SUMPRODUCT((LEFT('Purchase Orders'!E2:E481,7)=O31)*1) -> 20
O32: 2025-02 | P32: =SUMPRODUCT((LEFT('Purchase Orders'!E2:E481,7)=O32)*'Purchase Orders'!L2:L481) -> 197985818 | Q32: =SUMPRODUCT((LEFT('Purchase Orders'!E2:E481,7)=O32)*1) -> 20
O33: 2025-03 | P33: =SUMPRODUCT((LEFT('Purchase Orders'!E2:E481,7)=O33)*'Purchase Orders'!L2:L481) -> 263562650 | Q33: =SUMPRODUCT((LEFT('Purchase Orders'!E2:E481,7)=O33)*1) -> 20
O34: 2025-04 | P34: =SUMPRODUCT((LEFT('Purchase Orders'!E2:E481,7)=O34)*'Purchase Orders'!L2:L481) -> 228035788 | Q34: =SUMPRODUCT((LEFT('Purchase Orders'!E2:E481,7)=O34)*1) -> 20
O35: 2025-05 | P35: =SUMPRODUCT((LEFT('Purchase Orders'!E2:E481,7)=O35)*'Purchase Orders'!L2:L481) -> 226014919 | Q35: =SUMPRODUCT((LEFT('Purchase Orders'!E2:E481,7)=O35)*1) -> 20
O36: 2025-06 | P36: =SUMPRODUCT((LEFT('Purchase Orders'!E2:E481,7)=O36)*'Purchase Orders'!L2:L481) -> 131023757 | Q36: =SUMPRODUCT((LEFT('Purchase Orders'!E2:E481,7)=O36)*1) -> 20
O37: 2025-07 | P37: =SUMPRODUCT((LEFT('Purchase Orders'!E2:E481,7)=O37)*'Purchase Orders'!L2:L481) -> 201670837 | Q37: =SUMPRODUCT((LEFT('Purchase Orders'!E2:E481,7)=O37)*1) -> 20
O38: 2025-08 | P38: =SUMPRODUCT((LEFT('Purchase Orders'!E2:E481,7)=O38)*'Purchase Orders'!L2:L481) -> 120896669 | Q38: =SUMPRODUCT((LEFT('Purchase Orders'!E2:E481,7)=O38)*1) -> 20
O39: 2025-09 | P39: =SUMPRODUCT((LEFT('Purchase Orders'!E2:E481,7)=O39)*'Purchase Orders'!L2:L481) -> 177969679 | Q39: =SUMPRODUCT((LEFT('Purchase Orders'!E2:E481,7)=O39)*1) -> 20
O40: 2025-10 | P40: =SUMPRODUCT((LEFT('Purchase Orders'!E2:E481,7)=O40)*'Purchase Orders'!L2:L481) -> 199194387 | Q40: =SUMPRODUCT((LEFT('Purchase Orders'!E2:E481,7)=O40)*1) -> 20
O41: 2025-11 | P41: =SUMPRODUCT((LEFT('Purchase Orders'!E2:E481,7)=O41)*'Purchase Orders'!L2:L481) -> 208298960 | Q41: =SUMPRODUCT((LEFT('Purchase Orders'!E2:E481,7)=O41)*1) -> 20
O42: 2025-12 | P42: =SUMPRODUCT((LEFT('Purchase Orders'!E2:E481,7)=O42)*'Purchase Orders'!L2:L481) -> 244003342 | Q42: =SUMPRODUCT((LEFT('Purchase Orders'!E2:E481,7)=O42)*1) -> 20
...

Sheet Dashboard
B1: KENYA FLEET & LOGISTICS OPERATIONS DASHBOARD
B2: Reporting Period: January 2024 – December 2025 | Data Source: Fleet, Machinery, PO & Delivery Sheets
B4: TOTAL FLEET VEHICLES | D4: ACTIVE VEHICLES | F4: TOTAL FLEET COST | H4: AVG UTILIZATION | J4: TOTAL PURCHASE ORDERS | L4: ON-TIME DELIVERY RATE
B5: ='Fleet Data'!R2 -> 200 | D5: ='Fleet Data'!R3 -> 184 | F5: ='Fleet Data'!R6 -> 710114919 | H5: ='Fleet Data'!R7 -> 68.3735 | J5: =COUNTA('Purchase Orders'!A2:A481) -> 480 | L5: =COUNTIF('Purchase Orders'!O2:O481,"YES")/COUNTA('Purchase Orders'!O2:O481)*100 -> 54.375
B6: Units | D6: Units | F6: KES | H6: % | J6: POs | L6: %
B8: FLEET VEHICLES BY COUNTY (Top 10) | G8: PURCHASE ORDER STATUS SUMMARY
B9: County | C9: Vehicles | D9: Avg Cost/km | E9: Avg Util % | G9: Status | H9: Count | I9: Total Value (KES) | J9: % of Total
B10: Nairobi | C10: =COUNTIF('Fleet Data'!C2:C201,B10) -> 16 | D10: =AVERAGEIF('Fleet Data'!C2:C201,B10,'Fleet Data'!O2:O201) -> 24.147803 | E10: =AVERAGEIF('Fleet Data'!C2:C201,B10,'Fleet Data'!N2:N201) -> 63.175 | G10: Delivered | H10: =COUNTIF('Purchase Orders'!M2:M481,G10) -> 281 | I10: =SUMIF('Purchase Orders'!M2:M481,G10,'Purchase Orders'!L2:L481) -> 2869299912 | J10: =IF(COUNTA('Purchase Orders'!M2:M481)>0,H10/COUNTA('Purchase Orders'!M2:M481)*100,0) -> 58.541667
B11: Mombasa | C11: =COUNTIF('Fleet Data'!C2:C201,B11) -> 20 | D11: =AVERAGEIF('Fleet Data'!C2:C201,B11,'Fleet Data'!O2:O201) -> 24.327892 | E11: =AVERAGEIF('Fleet Data'!C2:C201,B11,'Fleet Data'!N2:N201) -> 71.73 | G11: In Transit | H11: =COUNTIF('Purchase Orders'!M2:M481,G11) -> 125 | I11: =SUMIF('Purchase Orders'!M2:M481,G11,'Purchase Orders'!L2:L481) -> 1389604939 | J11: =IF(COUNTA('Purchase Orders'!M2:M481)>0,H11/COUNTA('Purchase Orders'!M2:M481)*100,0) -> 26.041667
B12: Kisumu | C12: =COUNTIF('Fleet Data'!C2:C201,B12) -> 14 | D12: =AVERAGEIF('Fleet Data'!C2:C201,B12,'Fleet Data'!O2:O201) -> 24.1469 | E12: =AVERAGEIF('Fleet Data'!C2:C201,B12,'Fleet Data'!N2:N201) -> 69.714286 | G12: Pending | H12: =COUNTIF('Purchase Orders'!M2:M481,G12) -> 31 | I12: =SUMIF('Purchase Orders'!M2:M481,G12,'Purchase Orders'!L2:L481) -> 248262371 | J12: =IF(COUNTA('Purchase Orders'!M2:M481)>0,H12/COUNTA('Purchase Orders'!M2:M481)*100,0) -> 6.4583333
B13: Nakuru | C13: =COUNTIF('Fleet Data'!C2:C201,B13) -> 10 | D13: =AVERAGEIF('Fleet Data'!C2:C201,B13,'Fleet Data'!O2:O201) -> 23.881913 | E13: =AVERAGEIF('Fleet Data'!C2:C201,B13,'Fleet Data'!N2:N201) -> 71.82 | G13: Delayed | H13: =COUNTIF('Purchase Orders'!M2:M481,G13) -> 43 | I13: =SUMIF('Purchase Orders'!M2:M481,G13,'Purchase Orders'!L2:L481) -> 344908194 | J13: =IF(COUNTA('Purchase Orders'!M2:M481)>0,H13/COUNTA('Purchase Orders'!M2:M481)*100,0) -> 8.9583333
B14: Eldoret | C14: =COUNTIF('Fleet Data'!C2:C201,B14) -> 15 | D14: =AVERAGEIF('Fleet Data'!C2:C201,B14,'Fleet Data'!O2:O201) -> 21.987793 | E14: =AVERAGEIF('Fleet Data'!C2:C201,B14,'Fleet Data'!N2:N201) -> 54.74 | G14: Cancelled | H14: =COUNTIF('Purchase Orders'!M2:M481,G14) -> 0 | I14: =SUMIF('Purchase Orders'!M2:M481,G14,'Purchase Orders'!L2:L481) -> 0 | J14: =IF(COUNTA('Purchase Orders'!M2:M481)>0,H14/COUNTA('Purchase Orders'!M2:M481)*100,0) -> 0
B15: Thika | C15: =COUNTIF('Fleet Data'!C2:C201,B15) -> 8 | D15: =AVERAGEIF('Fleet Data'!C2:C201,B15,'Fleet Data'!O2:O201) -> 28.18066 | E15: =AVERAGEIF('Fleet Data'!C2:C201,B15,'Fleet Data'!N2:N201) -> 67.3
B16: Nyeri | C16: =COUNTIF('Fleet Data'!C2:C201,B16) -> 12 | D16: =AVERAGEIF('Fleet Data'!C2:C201,B16,'Fleet Data'!O2:O201) -> 23.130933 | E16: =AVERAGEIF('Fleet Data'!C2:C201,B16,'Fleet Data'!N2:N201) -> 62.308333
B17: Machakos | C17: =COUNTIF('Fleet Data'!C2:C201,B17) -> 10 | D17: =AVERAGEIF('Fleet Data'!C2:C201,B17,'Fleet Data'!O2:O201) -> 25.918376 | E17: =AVERAGEIF('Fleet Data'!C2:C201,B17,'Fleet Data'!N2:N201) -> 72.52
B18: Meru | C18: =COUNTIF('Fleet Data'!C2:C201,B18) -> 10 | D18: =AVERAGEIF('Fleet Data'!C2:C201,B18,'Fleet Data'!O2:O201) -> 20.540982 | E18: =AVERAGEIF('Fleet Data'!C2:C201,B18,'Fleet Data'!N2:N201) -> 80.02
B19: Kitale | C19: =COUNTIF('Fleet Data'!C2:C201,B19) -> 14 | D19: =AVERAGEIF('Fleet Data'!C2:C201,B19,'Fleet Data'!O2:O201) -> 26.722106 | E19: =AVERAGEIF('Fleet Data'!C2:C201,B19,'Fleet Data'!N2:N201) -> 74.307143
B22: MACHINERY UTILIZATION BY SITE | G22: TOP ROUTES – DELIVERY PERFORMANCE
B23: Site | C23: Avg Utilization (%) | D23: Total Hrs | E23: Breakdowns | G23: Route | H23: Deliveries | I23: Avg Delay (hrs) | J23: Total Cost (KES) | K23: Completion %
B24: Nairobi Bypass | C24: =AVERAGEIF('Machinery Log'!C2:C301,B24,'Machinery Log'!I2:I301) -> 70.35728 | D24: =SUMIF('Machinery Log'!C2:C301,B24,'Machinery Log'!G2:G301) -> 197.3 | E24: =SUMIF('Machinery Log'!C2:C301,B24,'Machinery Log'!L2:L301) -> 4 | G24: Nairobi→Mombasa | H24: =COUNTIF('Delivery Tracker'!B2:B401,G24) -> 23 | I24: =IFERROR(AVERAGEIF('Delivery Tracker'!B2:B401,G24,'Delivery Tracker'!J2:J401),0) -> 0.8 | J24: =SUMIF('Delivery Tracker'!B2:B401,G24,'Delivery Tracker'!Q2:Q401) -> 2053835 | K24: =IFERROR(COUNTIFS('Delivery Tracker'!B2:B401,G24,'Delivery Tracker'!O2:O401,"Completed")/H24*100,0) -> 56.521739
B25: Thika Road | C25: =AVERAGEIF('Machinery Log'!C2:C301,B25,'Machinery Log'!I2:I301) -> 72.556238 | D25: =SUMIF('Machinery Log'!C2:C301,B25,'Machinery Log'!G2:G301) -> 258.5 | E25: =SUMIF('Machinery Log'!C2:C301,B25,'Machinery Log'!L2:L301) -> 2 | G25: Nairobi→Kisumu | H25: =COUNTIF('Delivery Tracker'!B2:B401,G25) -> 29 | I25: =IFERROR(AVERAGEIF('Delivery Tracker'!B2:B401,G25,'Delivery Tracker'!J2:J401),0) -> 0.90689655 | J25: =SUMIF('Delivery Tracker'!B2:B401,G25,'Delivery Tracker'!Q2:Q401) -> 1867219 | K25: =IFERROR(COUNTIFS('Delivery Tracker'!B2:B401,G25,'Delivery Tracker'!O2:O401,"Completed")/H25*100,0) -> 79.310345
B26: Mombasa SGR | C26: =AVERAGEIF('Machinery Log'!C2:C301,B26,'Machinery Log'!I2:I301) -> 74.743232 | D26: =SUMIF('Machinery Log'!C2:C301,B26,'Machinery Log'!G2:G301) -> 188.4 | E26: =SUMIF('Machinery Log'!C2:C301,B26,'Machinery Log'!L2:L301) -> 6 | G26: Nairobi→Nakuru | H26: =COUNTIF('Delivery Tracker'!B2:B401,G26) -> 27 | I26: =IFERROR(AVERAGEIF('Delivery Tracker'!B2:B401,G26,'Delivery Tracker'!J2:J401),0) -> 0.53333333 | J26: =SUMIF('Delivery Tracker'!B2:B401,G26,'Delivery Tracker'!Q2:Q401) -> 832619 | K26: =IFERROR(COUNTIFS('Delivery Tracker'!B2:B401,G26,'Delivery Tracker'!O2:O401,"Completed")/H26*100,0) -> 81.481481
B27: Kisumu Port | C27: =AVERAGEIF('Machinery Log'!C2:C301,B27,'Machinery Log'!I2:I301) -> 71.265761 | D27: =SUMIF('Machinery Log'!C2:C301,B27,'Machinery Log'!G2:G301) -> 207.9 | E27: =SUMIF('Machinery Log'!C2:C301,B27,'Machinery Log'!L2:L301) -> 7 | G27: Mombasa→Malindi | H27: =COUNTIF('Delivery Tracker'!B2:B401,G27) -> 20 | I27: =IFERROR(AVERAGEIF('Delivery Tracker'!B2:B401,G27,'Delivery Tracker'!J2:J401),0) -> 0.23 | J27: =SUMIF('Delivery Tracker'!B2:B401,G27,'Delivery Tracker'!Q2:Q401) -> 420872 | K27: =IFERROR(COUNTIFS('Delivery Tracker'!B2:B401,G27,'Delivery Tracker'!O2:O401,"Completed")/H27*100,0) -> 70
B28: Eldoret Industrial | C28: =AVERAGEIF('Machinery Log'!C2:C301,B28,'Machinery Log'!I2:I301) -> 67.232812 | D28: =SUMIF('Machinery Log'!C2:C301,B28,'Machinery Log'!G2:G301) -> 207.4 | E28: =SUMIF('Machinery Log'!C2:C301,B28,'Machinery Log'!L2:L301) -> 5 | G28: Nakuru→Eldoret | H28: =COUNTIF('Delivery Tracker'!B2:B401,G28) -> 24 | I28: =IFERROR(AVERAGEIF('Delivery Tracker'!B2:B401,G28,'Delivery Tracker'!J2:J401),0) -> 0.3125 | J28: =SUMIF('Delivery Tracker'!B2:B401,G28,'Delivery Tracker'!Q2:Q401) -> 628471 | K28: =IFERROR(COUNTIFS('Delivery Tracker'!B2:B401,G28,'Delivery Tracker'!O2:O401,"Completed")/H28*100,0) -> 62.5
B29: Nyeri Dam | C29: =AVERAGEIF('Machinery Log'!C2:C301,B29,'Machinery Log'!I2:I301) -> 66.513986 | D29: =SUMIF('Machinery Log'!C2:C301,B29,'Machinery Log'!G2:G301) -> 179.4 | E29: =SUMIF('Machinery Log'!C2:C301,B29,'Machinery Log'!L2:L301) -> 4 | G29: Nairobi→Nyeri | H29: =COUNTIF('Delivery Tracker'!B2:B401,G29) -> 27 | I29: =IFERROR(AVERAGEIF('Delivery Tracker'!B2:B401,G29,'Delivery Tracker'!J2:J401),0) -> 0.28148148 | J29: =SUMIF('Delivery Tracker'!B2:B401,G29,'Delivery Tracker'!Q2:Q401) -> 745169 | K29: =IFERROR(COUNTIFS('Delivery Tracker'!B2:B401,G29,'Delivery Tracker'!O2:O401,"Completed")/H29*100,0) -> 62.962963
B30: Nakuru Ring Road | C30: =AVERAGEIF('Machinery Log'!C2:C301,B30,'Machinery Log'!I2:I301) -> 62.322971 | D30: =SUMIF('Machinery Log'!C2:C301,B30,'Machinery Log'!G2:G301) -> 183.6 | E30: =SUMIF('Machinery Log'!C2:C301,B30,'Machinery Log'!L2:L301) -> 2 | G30: Thika→Garissa | H30: =COUNTIF('Delivery Tracker'!B2:B401,G30) -> 34 | I30: =IFERROR(AVERAGEIF('Delivery Tracker'!B2:B401,G30,'Delivery Tracker'!J2:J401),0) -> 0.86470588 | J30: =SUMIF('Delivery Tracker'!B2:B401,G30,'Delivery Tracker'!Q2:Q401) -> 2293436 | K30: =IFERROR(COUNTIFS('Delivery Tracker'!B2:B401,G30,'Delivery Tracker'!O2:O401,"Completed")/H30*100,0) -> 67.647059
B31: Garissa Bridge | C31: =AVERAGEIF('Machinery Log'!C2:C301,B31,'Machinery Log'!I2:I301) -> 69.535272 | D31: =SUMIF('Machinery Log'!C2:C301,B31,'Machinery Log'!G2:G301) -> 219 | E31: =SUMIF('Machinery Log'!C2:C301,B31,'Machinery Log'!L2:L301) -> 3 | G31: Kisumu→Kisii | H31: =COUNTIF('Delivery Tracker'!B2:B401,G31) -> 33 | I31: =IFERROR(AVERAGEIF('Delivery Tracker'!B2:B401,G31,'Delivery Tracker'!J2:J401),0) -> 0.13636364 | J31: =SUMIF('Delivery Tracker'!B2:B401,G31,'Delivery Tracker'!Q2:Q401) -> 382545 | K31: =IFERROR(COUNTIFS('Delivery Tracker'!B2:B401,G31,'Delivery Tracker'!O2:O401,"Completed")/H31*100,0) -> 63.636364
B32: Malindi Resort | C32: =AVERAGEIF('Machinery Log'!C2:C301,B32,'Machinery Log'!I2:I301) -> 67.683622 | D32: =SUMIF('Machinery Log'!C2:C301,B32,'Machinery Log'!G2:G301) -> 182.7 | E32: =SUMIF('Machinery Log'!C2:C301,B32,'Machinery Log'!L2:L301) -> 3 | G32: Nairobi→Thika | H32: =COUNTIF('Delivery Tracker'!B2:B401,G32) -> 28 | I32: =IFERROR(AVERAGEIF('Delivery Tracker'!B2:B401,G32,'Delivery Tracker'!J2:J401),0) -> 0.14285714 | J32: =SUMIF('Delivery Tracker'!B2:B401,G32,'Delivery Tracker'!Q2:Q401) -> 226961 | K32: =IFERROR(COUNTIFS('Delivery Tracker'!B2:B401,G32,'Delivery Tracker'!O2:O401,"Completed")/H32*100,0) -> 89.285714
B33: Kitale Grain Store | C33: =AVERAGEIF('Machinery Log'!C2:C301,B33,'Machinery Log'!I2:I301) -> 67.828283 | D33: =SUMIF('Machinery Log'!C2:C301,B33,'Machinery Log'!G2:G301) -> 240.1 | E33: =SUMIF('Machinery Log'!C2:C301,B33,'Machinery Log'!L2:L301) -> 6 | G33: Mombasa→Nairobi | H33: =COUNTIF('Delivery Tracker'!B2:B401,G33) -> 22 | I33: =IFERROR(AVERAGEIF('Delivery Tracker'!B2:B401,G33,'Delivery Tracker'!J2:J401),0) -> 1.1090909 | J33: =SUMIF('Delivery Tracker'!B2:B401,G33,'Delivery Tracker'!Q2:Q401) -> 1993383 | K33: =IFERROR(COUNTIFS('Delivery Tracker'!B2:B401,G33,'Delivery Tracker'!O2:O401,"Completed")/H33*100,0) -> 77.272727
B35: KEY INSIGHTS & ANALYST NOTES
B36: • Fleet performance: Nairobi and Mombasa account for the highest fleet operating costs due to urban traffic and longer routes.
B37: • Machinery: Sites in Nairobi Bypass and Mombasa SGR show highest utilization but also highest breakdown frequency — recommend preventive maintenance.
B38: • Procurement: Delayed purchase orders are concentrated with 2–3 upcountry suppliers — renegotiate lead times or diversify supplier base.
B39: • Delivery: The Nairobi–Mombasa corridor has the highest total delivery cost; consolidation of loads recommended to reduce cost per trip.
B40: • Data Quality: 98.5% of records are complete; missing actual delivery dates on In-Transit & Pending POs are expected and acceptable.

Sheet README
B2: KENYA FLEET & LOGISTICS OPERATIONS ANALYSIS
B5: Portfolio Project | Junior Data Analyst | 2024–2025
B6: Analysing fleet performance, machinery utilization, purchase orders & delivery logistics across Kenya
B8: ANALYST | D8: Jane Wanjiku Kamau
B9: PERIOD | D9: January 2024 – December 2025
B10: DATASET | D10: 2,400 records | 6 worksheets
B11: TOOLS USED | D11: Microsoft Excel (Pivot Tables, VLOOKUP, IFs, Charts, Conditional Formatting)
B12: DOMAIN | D12: Fleet Management, Procurement, Logistics – Kenya
B14: KEY BUSINESS QUESTIONS ANSWERED
B15: 1. Which counties have the highest fleet operating costs?
B16: 2. What is the average machinery utilization rate across regions?
B17: 3. Which suppliers have the most delayed deliveries?
B18: 4. What is the monthly trend in purchase order values?
B19: 5. Which vehicle categories consume the most fuel?
B20: 6. What is the on-time delivery rate by product category?
B21: 7. Where are inventory shortfalls occurring?
B22: 8. What are the top 5 cost-driving routes in the fleet?
B24: WORKBOOK SHEETS
B25: 📊 Fleet Data | D25: Raw fleet vehicle data: 200 vehicles, mileage, fuel, costs by county
B26: 🔧 Machinery Log | D26: Machinery utilization log: 300 entries across construction sites
B27: 📦 Purchase Orders | D27: 480 purchase orders with suppliers, delivery dates & status
B28: 🗺️ Delivery Tracker | D28: Delivery route performance: distance, time, delays per region
B29: 📈 Dashboard | D29: Executive summary dashboard with KPIs and charts
